Traceback (most recent call last):
  File "/home/szhou3/resilient_compute/resilience_test/expanse/retry/ulimit/main.py", line 32, in <module>
    print(result.result())
  File "/home/szhou3/.conda/envs/parsl310/lib/python3.10/concurrent/futures/_base.py", line 458, in result
    return self.__get_result()
  File "/home/szhou3/.conda/envs/parsl310/lib/python3.10/concurrent/futures/_base.py", line 403, in __get_result
    raise self._exception
  File "/home/szhou3/parsl_resilient/parsl/dataflow/dflow.py", line 320, in handle_exec_update
    res = self._unwrap_remote_exception_wrapper(future)
  File "/home/szhou3/parsl_resilient/parsl/dataflow/dflow.py", line 592, in _unwrap_remote_exception_wrapper
    result.reraise()
  File "/home/szhou3/parsl_resilient/parsl/app/errors.py", line 118, in reraise
    raise v
  File "/home/szhou3/parsl_resilient/parsl/app/errors.py", line 141, in wrapper
    return func(*args, **kwargs)
  File "/home/szhou3/resilient_compute/resilience_test/expanse/retry/ulimit/main.py", line 21, in open_many_files
    handles.append(open(f"/tmp/tempfile_{socket.gethostname()}_{i}.txt", "w"))
OSError: [Errno 23] Too many open files in system: '/tmp/tempfile_exp-9-55_543730.txt'
