Traceback (most recent call last):
  File "/home/szhou3/resilient_compute/resilience_test/expanse/permanent/environment/main.py", line 18, in <module>
    [t.result() for t in tasks]
  File "/home/szhou3/resilient_compute/resilience_test/expanse/permanent/environment/main.py", line 18, in <listcomp>
    [t.result() for t in tasks]
  File "/home/szhou3/.conda/envs/parsl310/lib/python3.10/concurrent/futures/_base.py", line 458, in result
    return self.__get_result()
  File "/home/szhou3/.conda/envs/parsl310/lib/python3.10/concurrent/futures/_base.py", line 403, in __get_result
    raise self._exception
  File "/home/szhou3/parsl_resilient/parsl/dataflow/dflow.py", line 320, in handle_exec_update
    res = self._unwrap_remote_exception_wrapper(future)
  File "/home/szhou3/parsl_resilient/parsl/dataflow/dflow.py", line 592, in _unwrap_remote_exception_wrapper
    result.reraise()
  File "/home/szhou3/parsl_resilient/parsl/app/errors.py", line 118, in reraise
    raise v
  File "/home/szhou3/parsl_resilient/parsl/app/errors.py", line 141, in wrapper
    return func(*args, **kwargs)
  File "/home/szhou3/resilient_compute/resilience_test/expanse/permanent/environment/main.py", line 12, in env_err
    import non_exist
ModuleNotFoundError: No module named 'non_exist'
