Traceback (most recent call last):
  File "/home/szhou3/resilient_compute/resilience_test/expanse/walltime/main.py", line 18, in <module>
    [t.result() for t in tasks]
  File "/home/szhou3/resilient_compute/resilience_test/expanse/walltime/main.py", line 18, in <listcomp>
    [t.result() for t in tasks]
  File "/home/szhou3/.conda/envs/parsl310/lib/python3.10/concurrent/futures/_base.py", line 458, in result
    return self.__get_result()
  File "/home/szhou3/.conda/envs/parsl310/lib/python3.10/concurrent/futures/_base.py", line 403, in __get_result
    raise self._exception
  File "/home/szhou3/parsl_resilient/parsl/dataflow/dflow.py", line 320, in handle_exec_update
    res = self._unwrap_remote_exception_wrapper(future)
  File "/home/szhou3/parsl_resilient/parsl/dataflow/dflow.py", line 590, in _unwrap_remote_exception_wrapper
    result = future.result()
  File "/home/szhou3/.conda/envs/parsl310/lib/python3.10/concurrent/futures/_base.py", line 451, in result
    return self.__get_result()
  File "/home/szhou3/.conda/envs/parsl310/lib/python3.10/concurrent/futures/_base.py", line 403, in __get_result
    raise self._exception
  File "/home/szhou3/parsl_resilient/parsl/executors/high_throughput/executor.py", line 484, in _queue_management_worker
    s.reraise()
  File "/home/szhou3/parsl_resilient/parsl/app/errors.py", line 118, in reraise
    raise v
  File "/home/szhou3/parsl_resilient/parsl/executors/high_throughput/interchange.py", line 591, in expire_bad_managers
    raise ManagerLost(manager_id, m['hostname'])
parsl.executors.high_throughput.interchange.ManagerLost: Task failure due to loss of manager 2e8fd7cf61c5 on host exp-9-55
make: *** [Makefile:10: run] Error 1